Workbook

Sheet Crawford Central School 26-27
A1: From Top | B1: Old System | C1: Nurse Tech | D1: Bachelors | E1: B+15 | F1: Masters | G1: M+15 | J1: Step | K1: Voc I | L1: Voc I Difference | M1: Voc II | N1: M | O1: M+15
A2: 13 | B2: 1 | C2: 36867 | D2: 54237 | E2: 57447 | F2: 61097 | G2: 64538 | J2: 1 | K2: 0 | M2: 0 | N2: 0 | O2: 0
A3: 12 | B3: 2 | C3: 37703 | D3: 54537 | E3: 57747 | F3: 61397 | G3: 64838 | J3: 2 | K3: 45208 | L3: =K3 - D3 -> -9329 | M3: 45731 | N3: 46749 | O3: 47749
A4: 11 | B4: 3 | C4: 38538 | D4: 54837 | E4: 58047 | F4: 61697 | G4: 65138 | J4: 3 | K4: 45808 | L4: =K4 - D4 -> -9029 | M4: 46331 | N4: 47349 | O4: 48349
A5: 10 | B5: 4 | C5: 39374 | D5: 55137 | E5: 58347 | F5: 61997 | G5: 65438 | J5: 4 | K5: 46408 | L5: =K5 - D5 -> -8729 | M5: 46931 | N5: 47949 | O5: 48949
A6: 9 | B6: 5 | C6: 40209 | D6: 55437 | E6: 58647 | F6: 62297 | G6: 66738 | J6: 5 | K6: 47408 | L6: =K6 - D6 -> -8029 | M6: 47931 | N6: 48949 | O6: 49949
A7: 8 | B7: 6 | C7: 41046 | D7: 55737 | E7: 58947 | F7: 62597 | G7: 66838 | J7: 6 | K7: 48408 | L7: =K7 - D7 -> -7329 | M7: 48931 | N7: 49949 | O7: 50949
A8: 7 | B8: 7 | C8: 41881 | D8: 58240 | E8: 59897 | F8: 63547 | G8: 66988 | J8: 7 | K8: 49458 | L8: =K8 - D8 -> -8782 | M8: 49981 | N8: 50999 | O8: 51999
A9: 6 | B9: 8 | C9: 42716 | D9: 56744 | E9: 60832 | F9: 64482 | G9: 67923 | J9: 8 | K9: 50358 | L9: =K9 - D9 -> -6386 | M9: 50881 | N9: 51899 | O9: 52899
A10: 5 | B10: 9 | C10: 43552 | D10: 57247 | E10: 61768 | F10: 65418 | G10: 68869 | J10: 9 | K10: 51158 | L10: =K10 - D10 -> -6089 | M10: 51681 | N10: 52699 | O10: 53699
A11: 4 | B11: 10 | C11: 44387 | D11: 60177 | E11: 62698 | F11: 66348 | G11: 69789 | J11: 10 | K11: 52008 | L11: =K11 - D11 -> -8169 | M11: 52531 | N11: 53549 | O11: 54549
A12: 3 | B12: 11 | C12: 46223 | D12: 60418 | E12: 64939 | F12: 68689 | G12: 72030 | J12: 11 | K12: 52758 | L12: =K12 - D12 -> -7660 | M12: 53281 | N12: 54299 | O12: 55299
A13: 2 | B13: 12 | C13: 46059 | D13: 62659 | E13: 67180 | F13: 70830 | G13: 74271 | J13: 12 | K13: 53408 | L13: =K13 - D13 -> -9251 | M13: 53931 | N13: 54949 | O13: 55949
A14: 1 | B14: 13 | C14: 46894 | D14: 64900 | E14: 69421 | F14: 73071 | G14: 76512 | J14: 13 | K14: 54158 | L14: =K14 - D14 -> -10742 | M14: 54681 | N14: 55699 | O14: 56699
... A22: 0 | B22: 21 | C22: 47730 | D22: 67141 | E22: 73609 | F22: 76312 | G22: 78753 | J22: 21 | K22: 73574 | L22: =K22 - D22 -> 6433 | M22: 74846 | N22: 75615 | O22: 75715
A26: Crawford Hours:
A27: 7.5 hr day with 30 minutes duty free
A28: 185 days
A29: 6 additional hours for open house and meetings
A31: days | B31: 185
A32: min-per-day (counting duty free) | B32: 450
A33: hours-per-day | B33: =B32/60 -> 7.5
A34: additional hours | B34: 6
A35: total hours | B35: =(B31*B33)+B34 -> 1393.5

Sheet Corry 23-24
A1: NOTE: Corry's numbers are from the 23-24 school year. Many contracts have significantly gone up since then
A2: From Top | B2: In Contract | C2: Voc. 1 | D2: Voc. 2 | E2: Bachelors | F2: B+24 | G2: M/ME | H2: M+15 | I2: M+30 | L2: Step | M2: Voc I | N2: Voc I Difference | O2: Voc II | P2: M | Q2: M+15
A3: 15 | B3: 1 | C3: 42108 | D3: 44292 | E3: 46405 | F3: 48908 | G3: 50240 | H3: 51540 | I3: 52840 | L3: 1 | M3: 0 | O3: 0 | P3: 0 | Q3: 0
A4: 14 | B4: 2 | C4: 42628 | D4: 44712 | E4: 46825 | F4: 49363 | G4: 50705 | H4: 52010 | I4: 53315 | L4: 2 | M4: 45208 | N4: =M4 - C4 -> 2580 | O4: 45731 | P4: 46749 | Q4: 47749
A5: 13 | B5: 3 | C5: 42948 | D5: 45132 | E5: 47245 | F5: 49808 | G5: 51156 | H5: 52466 | I5: 53775 | L5: 3 | M5: 45808 | N5: =M5 - C5 -> 2860 | O5: 46331 | P5: 47349 | Q5: 48349
A6: 12 | B6: 4 | C6: 43369 | D6: 45553 | E6: 47666 | F6: 50299 | G6: 51661 | H6: 52976 | I6: 54286 | L6: 4 | M6: 46408 | N6: =M6 - C6 -> 3039 | O6: 46931 | P6: 47949 | Q6: 48949
A7: 11 | B7: 5 | C7: 43824 | D7: 46008 | E7: 48121 | F7: 50754 | G7: 52116 | H7: 53431 | I7: 54741 | L7: 5 | M7: 47408 | N7: =M7 - C7 -> 3584 | O7: 47931 | P7: 48949 | Q7: 49949
A8: 10 | B8: 6 | C8: 45100 | D8: 47283 | E8: 49396 | F8: 52105 | G8: 53567 | H8: 54942 | I8: 56381 | L8: 6 | M8: 48408 | N8: =M8 - C8 -> 3308 | O8: 48931 | P8: 49949 | Q8: 50949
A9: 9 | B9: 7 | C9: 46603 | D9: 48787 | E9: 50900 | F9: 53608 | G9: 55070 | H9: 56445 | I9: 57885 | L9: 7 | M9: 49458 | N9: =M9 - C9 -> 2855 | O9: 49981 | P9: 50999 | Q9: 51999
A10: 8 | B10: 8 | C10: 48183 | D10: 50365 | E10: 52478 | F10: 55188 | G10: 56650 | H10: 58025 | I10: 59464 | L10: 8 | M10: 50358 | N10: =M10 - C10 -> 2175 | O10: 50881 | P10: 51899 | Q10: 52899
A11: 7 | B11: 9 | C11: 49836 | D11: 52020 | E11: 54133 | F11: 56841 | G11: 58304 | H11: 59679 | I11: 61119 | L11: 9 | M11: 51158 | N11: =M11 - C11 -> 1322 | O11: 51681 | P11: 52699 | Q11: 53699
A12: 6 | B12: 10 | C12: 51416 | D12: 53599 | E12: 55712 | F12: 58421 | G12: 59883 | H12: 61258 | I12: 62697 | L12: 10 | M12: 52008 | N12: =M12 - C12 -> 592 | O12: 52531 | P12: 53549 | Q12: 54549
A13: 5 | B13: 11 | C13: 52994 | D13: 55178 | E13: 57291 | F13: 59999 | G13: 61462 | H13: 62838 | I13: 64277 | L13: 11 | M13: 52758 | N13: =M13 - C13 -> -236 | O13: 53281 | P13: 54299 | Q13: 55299
A14: 4 | B14: 12 | C14: 54574 | D14: 56757 | E14: 58870 | F14: 61579 | G14: 63041 | H14: 64416 | I14: 65855 | L14: 12 | M14: 53408 | N14: =M14 - C14 -> -1166 | O14: 53931 | P14: 54949 | Q14: 55949
A15: 3 | B15: 13 | C15: 56152 | D15: 58336 | E15: 60449 | F15: 63157 | G15: 64620 | H15: 65995 | I15: 67435 | L15: 13 | M15: 54158 | N15: =M15 - C15 -> -1994 | O15: 54681 | P15: 55699 | Q15: 56699
... A23: 0 | B23: 21 | C23: 61547 | D23: 63730 | E23: 65843 | F23: 68978 | G23: 70440 | H23: 71815 | I23: 73254 | L23: 21 | M23: 73574 | N23: =M23 - C23 -> 12027 | O23: 74846 | P23: 75615 | Q23: 75715
A25: Corry
A26: 7.5 hr day with 30 minutes duty free
A27: 185 days
A29: days | B29: 185
A30: min-per-day (counting duty free) | B30: 450
A31: hours-per-day | B31: =B30/60 -> 7.5
A32: additional hours
A33: total hours | B33: =(B29*B31)+B32 -> 1387.5

Sheet Mercer 26-27
A1: Steps | B1: Bachelors | C1: Masters | D1: M+15 | E1: M+30 | G1: Step | H1: Voc I | J1: Voc II | K1: M | L1: M+15
A2: 1 | B2: 56750 | C2: 58739 | D2: 60894 | E2: 63048 | G2: 1 | H2: 0 | J2: 0 | K2: 0 | L2: 0
A3: 2 | B3: 57057 | C3: 59046 | D3: 61201 | E3: 63355 | G3: 2 | H3: 45208 | I3: =H3-B3 -> -11849 | J3: 45731 | K3: 46749 | L3: 47749
A4: 3 | B4: 57364 | C4: 59353 | D4: 61508 | E4: 63662 | G4: 3 | H4: 45808 | I4: =H4-B4 -> -11556 | J4: 46331 | K4: 47349 | L4: 48349
A5: 4 | B5: 57671 | C5: 59660 | D5: 61815 | E5: 63969 | G5: 4 | H5: 46408 | I5: =H5-B5 -> -11263 | J5: 46931 | K5: 47949 | L5: 48949
A6: 5 | B6: 59123 | C6: 61112 | D6: 63266 | E6: 65421 | G6: 5 | H6: 47408 | I6: =H6-B6 -> -11715 | J6: 47931 | K6: 48949 | L6: 49949
A7: 6 | B7: 60575 | C7: 62564 | D7: 64718 | E7: 66873 | G7: 6 | H7: 48408 | I7: =H7-B7 -> -12167 | J7: 48931 | K7: 49949 | L7: 50949
A8: 7 | B8: 62027 | C8: 64015 | D8: 66170 | E8: 68324 | G8: 7 | H8: 49458 | I8: =H8-B8 -> -12569 | J8: 49981 | K8: 50999 | L8: 51999
A9: 8 | B9: 63479 | C9: 65467 | D9: 67622 | E9: 69776 | G9: 8 | H9: 50358 | I9: =H9-B9 -> -13121 | J9: 50881 | K9: 51899 | L9: 52899
A10: 9 | B10: 64930 | C10: 66919 | D10: 69074 | E10: 71228 | G10: 9 | H10: 51158 | I10: =H10-B10 -> -13772 | J10: 51681 | K10: 52699 | L10: 53699
A11: 10 | B11: 66382 | C11: 68371 | D11: 70525 | E11: 72680 | G11: 10 | H11: 52008 | I11: =H11-B11 -> -14374 | J11: 52531 | K11: 53549 | L11: 54549
A12: 11 | B12: 67834 | C12: 69823 | D12: 71977 | E12: 74132 | G12: 11 | H12: 52758 | I12: =H12-B12 -> -15076 | J12: 53281 | K12: 54299 | L12: 55299
A13: 12 | B13: 69286 | C13: 71274 | D13: 73429 | E13: 75583 | G13: 12 | H13: 53408 | I13: =H13-B13 -> -15878 | J13: 53931 | K13: 54949 | L13: 55949
A14: 13 | B14: 70737 | C14: 72726 | D14: 74881 | E14: 77035 | G14: 13 | H14: 54158 | I14: =H14-B14 -> -16579 | J14: 54681 | K14: 55699 | L14: 56699
... A22: 21 | B22: 77996 | C22: 79985 | D22: 82139 | E22: 84294 | G22: 21 | H22: 73574 | I22: =H22-B22 -> -4422 | J22: 74846 | K22: 75615 | L22: 75715
A25: Mercer
A26: 185 days
A28: days | B28: 185
A29: min-per-day (counting duty free) | B29: 450
A30: hours-per-day | B30: =B29/60 -> 7.5
A31: additional hours
A32: total hours | B32: =(B28*B30)+B31 -> 1387.5

Sheet Erie School District 26-27
A1: To Top | B1: Steps | C1: B | D1: B+6 | E1: B+12 | F1: B+18 | G1: B+24 | H1: B+30 | I1: M | J1: M+6 | K1: M+12 | L1: M+18 | M1: M+24 | N1: M+30 | O1: M+36 | P1: M+42 | Q1: M+48 | R1: M+54 | S1: M+60 | T1: Doc | V1: Step | W1: Voc I | Y1: Voc II | Z1: M | AA1: M+15
A2: 14 | B2: 1 | C2: 57646 | D2: 58123 | E2: 58601 | F2: 59079 | G2: 59556 | H2: 60034 | I2: 61949 | J2: 62445 | K2: 62940 | L2: 63435 | M2: 64709 | N2: 65205 | O2: 65702 | P2: 66199 | Q2: 66695 | R2: 67192 | S2: 67689 | T2: 68185 | V2: 1 | W2: 0 | Y2: 0 | Z2: 0 | AA2: 0
A3: 13 | B3: 2 | C3: 59039 | D3: 59516 | E3: 59994 | F3: 60472 | G3: 60949 | H3: 61427 | I3: 63529 | J3: 64025 | K3: 64520 | L3: 65015 | M3: 66289 | N3: 66785 | O3: 67282 | P3: 67779 | Q3: 68275 | R3: 68772 | S3: 69269 | T3: 69765 | V3: 2 | W3: 45208 | X3: =W3-C3 -> -13831 | Y3: 45731 | Z3: 46749 | AA3: 47749
A4: 12 | B4: 3 | C4: 60432 | D4: 60909 | E4: 61387 | F4: 61865 | G4: 62342 | H4: 62820 | I4: 65109 | J4: 65605 | K4: 66100 | L4: 66595 | M4: 67869 | N4: 68365 | O4: 68862 | P4: 69359 | Q4: 69855 | R4: 70352 | S4: 70849 | T4: 71345 | V4: 3 | W4: 45808 | X4: =W4-C4 -> -14624 | Y4: 46331 | Z4: 47349 | AA4: 48349
A5: 11 | B5: 4 | C5: 61825 | D5: 62302 | E5: 62780 | F5: 63258 | G5: 63735 | H5: 64213 | I5: 66689 | J5: 67185 | K5: 67680 | L5: 68175 | M5: 69449 | N5: 69945 | O5: 70442 | P5: 70939 | Q5: 71435 | R5: 71932 | S5: 72429 | T5: 72925 | V5: 4 | W5: 46408 | X5: =W5-C5 -> -15417 | Y5: 46931 | Z5: 47949 | AA5: 48949
A6: 10 | B6: 5 | C6: 63218 | D6: 63695 | E6: 64173 | F6: 64651 | G6: 65128 | H6: 65606 | I6: 68269 | J6: 68765 | K6: 69260 | L6: 69755 | M6: 71029 | N6: 71525 | O6: 72022 | P6: 72519 | Q6: 73015 | R6: 73512 | S6: 74009 | T6: 74505 | V6: 5 | W6: 47408 | X6: =W6-C6 -> -15810 | Y6: 47931 | Z6: 48949 | AA6: 49949
A7: 9 | B7: 6 | C7: 64611 | D7: 65088 | E7: 65566 | F7: 66044 | G7: 66521 | H7: 66999 | I7: 69849 | J7: 70345 | K7: 70840 | L7: 71335 | M7: 72609 | N7: 73105 | O7: 73602 | P7: 74099 | Q7: 74595 | R7: 75092 | S7: 75589 | T7: 76085 | V7: 6 | W7: 48408 | X7: =W7-C7 -> -16203 | Y7: 48931 | Z7: 49949 | AA7: 50949
A8: 8 | B8: 7 | C8: 66004 | D8: 66481 | E8: 66959 | F8: 67437 | G8: 67914 | H8: 68392 | I8: 71429 | J8: 71925 | K8: 72420 | L8: 72915 | M8: 74189 | N8: 74685 | O8: 75182 | P8: 75679 | Q8: 76175 | R8: 76672 | S8: 77169 | T8: 77665 | V8: 7 | W8: 49458 | X8: =W8-C8 -> -16546 | Y8: 49981 | Z8: 50999 | AA8: 51999
A9: 7 | B9: 8 | C9: 67397 | D9: 67874 | E9: 68352 | F9: 68830 | G9: 69307 | H9: 69785 | I9: 73009 | J9: 73505 | K9: 74000 | L9: 74495 | M9: 75769 | N9: 76265 | O9: 76762 | P9: 77259 | Q9: 77755 | R9: 78252 | S9: 78749 | T9: 79245 | V9: 8 | W9: 50358 | X9: =W9-C9 -> -17039 | Y9: 50881 | Z9: 51899 | AA9: 52899
A10: 6 | B10: 9 | C10: 68790 | D10: 69267 | E10: 69745 | F10: 70223 | G10: 70700 | H10: 71178 | I10: 74589 | J10: 75085 | K10: 75580 | L10: 76075 | M10: 77349 | N10: 77845 | O10: 78342 | P10: 78839 | Q10: 79335 | R10: 79832 | S10: 80329 | T10: 80825 | V10: 9 | W10: 51158 | X10: =W10-C10 -> -17632 | Y10: 51681 | Z10: 52699 | AA10: 53699
A11: 5 | B11: 10 | C11: 70183 | D11: 70660 | E11: 71138 | F11: 71616 | G11: 72093 | H11: 72571 | I11: 76169 | J11: 76665 | K11: 77160 | L11: 77655 | M11: 78929 | N11: 79425 | O11: 79922 | P11: 80419 | Q11: 80915 | R11: 81412 | S11: 81909 | T11: 82405 | V11: 10 | W11: 52008 | X11: =W11-C11 -> -18175 | Y11: 52531 | Z11: 53549 | AA11: 54549
A12: 4 | B12: 11 | C12: 71576 | D12: 72053 | E12: 72531 | F12: 73009 | G12: 73486 | H12: 73964 | I12: 77749 | J12: 78245 | K12: 78740 | L12: 79235 | M12: 80509 | N12: 81005 | O12: 81502 | P12: 81999 | Q12: 82495 | R12: 82992 | S12: 83489 | T12: 83985 | V12: 11 | W12: 52758 | X12: =W12-C12 -> -18818 | Y12: 53281 | Z12: 54299 | AA12: 55299
A13: 3 | B13: 12 | C13: 72969 | D13: 73446 | E13: 73924 | F13: 74402 | G13: 74879 | H13: 75357 | I13: 79329 | J13: 79825 | K13: 80320 | L13: 80815 | M13: 82089 | N13: 82585 | O13: 83082 | P13: 83579 | Q13: 84075 | R13: 84572 | S13: 85069 | T13: 85565 | V13: 12 | W13: 53408 | X13: =W13-C13 -> -19561 | Y13: 53931 | Z13: 54949 | AA13: 55949
A14: 2 | B14: 13 | C14: 74362 | D14: 74839 | E14: 75317 | F14: 75795 | G14: 76272 | H14: 76750 | I14: 80909 | J14: 81405 | K14: 81900 | L14: 82395 | M14: 83669 | N14: 84165 | O14: 84662 | P14: 85159 | Q14: 85655 | R14: 86152 | S14: 86649 | T14: 87145 | V14: 13 | W14: 54158 | X14: =W14-C14 -> -20204 | Y14: 54681 | Z14: 55699 | AA14: 56699
A15: 1 | B15: 14 | C15: 75755 | D15: 76232 | E15: 76710 | F15: 77188 | G15: 77665 | H15: 78143 | I15: 82489 | J15: 82985 | K15: 83480 | L15: 83975 | M15: 85249 | N15: 85745 | O15: 86242 | P15: 86739 | Q15: 87235 | R15: 87732 | S15: 88229 | T15: 88725 | V15: 14 | W15: 55158 | X15: =W15-C15 -> -20597 | Y15: 55681 | Z15: 56699 | AA15: 57699
A16: Top | B16: 15 | C16: 77148 | D16: 77625 | E16: 78103 | F16: 78581 | G16: 79058 | H16: 79536 | I16: 84069 | J16: 84565 | K16: 85060 | L16: 85555 | M16: 86829 | N16: 87325 | O16: 87822 | P16: 88319 | Q16: 88815 | R16: 89312 | S16: 89809 | T16: 90305 | V16: 15 | W16: 56458 | X16: =W16-C16 -> -20690 | Y16: 56981 | Z16: 57999 | AA16: 58999
A17: Top | B17: 16 | C17: 77148 | D17: 77625 | E17: 78103 | F17: 78581 | G17: 79058 | H17: 79536 | I17: 84069 | J17: 84565 | K17: 85060 | L17: 85555 | M17: 86829 | N17: 87325 | O17: 87822 | P17: 88319 | Q17: 88815 | R17: 89312 | S17: 89809 | T17: 90305 | V17: 16 | W17: 57758 | X17: =W17-C17 -> -19390 | Y17: 58281 | Z17: 59299 | AA17: 60299
A18: Top | B18: 17 | C18: 77148 | D18: 77625 | E18: 78103 | F18: 78581 | G18: 79058 | H18: 79536 | I18: 84069 | J18: 84565 | K18: 85060 | L18: 85555 | M18: 86829 | N18: 87325 | O18: 87822 | P18: 88319 | Q18: 88815 | R18: 89312 | S18: 89809 | T18: 90305 | V18: 17 | W18: 59308 | X18: =W18-C18 -> -17840 | Y18: 59831 | Z18: 60849 | AA18: 61849
A19: Top | B19: 18 | C19: 77148 | D19: 77625 | E19: 78103 | F19: 78581 | G19: 79058 | H19: 79536 | I19: 84069 | J19: 84565 | K19: 85060 | L19: 85555 | M19: 86829 | N19: 87325 | O19: 87822 | P19: 88319 | Q19: 88815 | R19: 89312 | S19: 89809 | T19: 90305 | V19: 18 | W19: 61908 | X19: =W19-C19 -> -15240 | Y19: 62431 | Z19: 63449 | AA19: 64449
A20: Top | B20: 19 | C20: 77148 | D20: 77625 | E20: 78103 | F20: 78581 | G20: 79058 | H20: 79536 | I20: 84069 | J20: 84565 | K20: 85060 | L20: 85555 | M20: 86829 | N20: 87325 | O20: 87822 | P20: 88319 | Q20: 88815 | R20: 89312 | S20: 89809 | T20: 90305 | V20: 19 | W20: 65958 | X20: =W20-C20 -> -11190 | Y20: 66481 | Z20: 67499 | AA20: 68499
A21: Top | B21: 20 | C21: 77148 | D21: 77625 | E21: 78103 | F21: 78581 | G21: 79058 | H21: 79536 | I21: 84069 | J21: 84565 | K21: 85060 | L21: 85555 | M21: 86829 | N21: 87325 | O21: 87822 | P21: 88319 | Q21: 88815 | R21: 89312 | S21: 89809 | T21: 90305 | V21: 20 | W21: 69533 | X21: =W21-C21 -> -7615 | Y21: 70056 | Z21: 71074 | AA21: 72074
A22: Top | B22: 21 | C22: 77148 | D22: 77625 | E22: 78103 | F22: 78581 | G22: 79058 | H22: 79536 | I22: 84069 | J22: 84565 | K22: 85060 | L22: 85555 | M22: 86829 | N22: 87325 | O22: 87822 | P22: 88319 | Q22: 88815 | R22: 89312 | S22: 89809 | T22: 90305 | V22: 21 | W22: 73574 | X22: =W22-C22 -> -3574 | Y22: 74846 | Z22: 75615 | AA22: 75715
A24: Erie School District
A25: 7hr10min workday?
A26: "The total regular work day shall average seven (7) hours and ten (10) minutes, inclusive of lunch periods, instructional periods, preparation and/or planning periods, and rest breaks where applicable."
A27: 185 days
A29: days | B29: 185
A30: min-per-day (counting duty free) | B30: 430
A31: hours-per-day | B31: =B30/60 -> 7.1666667
A32: additional hours
A33: total hours | B33: =(B29*B31)+B32 -> 1325.8333

Sheet North East 26-27
A1: Old Step | B1: Step | C1: Bachelors | D1: Masters | E1: M+6 | F1: M+12 | G1: M+18 | H1: M+24 | I1: M+30 | J1: M+36 | K1: M+42 | L1: M+48 | M1: D
A2: 5 | B2: 1 | C2: 55632 | D2: 56732 | E2: 57132 | F2: 57532 | G2: 57932 | H2: 58332 | I2: 58732 | J2: 59132 | K2: 59532 | L2: 59932 | M2: 60332
A3: 6 | B3: 2 | C3: 56632 | D3: 57732 | E3: 58132 | F3: 58532 | G3: 58932 | H3: 59332 | I3: 59732 | J3: 60132 | K3: 60532 | L3: 60932 | M3: 61332
A4: 7 | B4: 3 | C4: 57632 | D4: 58732 | E4: 59132 | F4: 59532 | G4: 59932 | H4: 60332 | I4: 60732 | J4: 61132 | K4: 61532 | L4: 61932 | M4: 62332
A5: 8 | B5: 4 | C5: 58632 | D5: 59732 | E5: 60132 | F5: 60532 | G5: 60932 | H5: 61332 | I5: 61732 | J5: 62132 | K5: 62532 | L5: 62932 | M5: 63332
A6: 9 | B6: 5 | C6: 59632 | D6: 60732 | E6: 61132 | F6: 61532 | G6: 61932 | H6: 62332 | I6: 62732 | J6: 63132 | K6: 63532 | L6: 63932 | M6: 64332
A7: 10 | B7: 6 | C7: 60632 | D7: 61732 | E7: 62132 | F7: 62532 | G7: 62932 | H7: 63332 | I7: 63732 | J7: 64132 | K7: 64532 | L7: 64932 | M7: 65332
A8: 11 | B8: 7 | C8: 61632 | D8: 62732 | E8: 63132 | F8: 63532 | G8: 63932 | H8: 64332 | I8: 64732 | J8: 65132 | K8: 65532 | L8: 65932 | M8: 66332
A9: 12 | B9: 8 | C9: 62632 | D9: 63732 | E9: 64132 | F9: 64532 | G9: 64932 | H9: 65332 | I9: 65732 | J9: 66132 | K9: 66532 | L9: 66932 | M9: 67332
A10: 13 | B10: 9 | C10: 63632 | D10: 64732 | E10: 65132 | F10: 65532 | G10: 65932 | H10: 66332 | I10: 66732 | J10: 67132 | K10: 67532 | L10: 67932 | M10: 68332
A11: 14 | B11: 10 | C11: 64632 | D11: 65732 | E11: 66132 | F11: 66532 | G11: 66932 | H11: 67332 | I11: 67732 | J11: 68132 | K11: 68532 | L11: 68932 | M11: 69332
A12: 15 | B12: 11 | C12: 65632 | D12: 66732 | E12: 67132 | F12: 67532 | G12: 67932 | H12: 68332 | I12: 68732 | J12: 69132 | K12: 69532 | L12: 69932 | M12: 70332
A13: 16 | B13: 12 | C13: 66632 | D13: 67732 | E13: 68132 | F13: 68532 | G13: 68932 | H13: 69332 | I13: 69732 | J13: 70132 | K13: 70532 | L13: 70932 | M13: 71332
... A21: 25 | B21: 20 | C21: 82487 | D21: 83751 | E21: 84151 | F21: 84551 | G21: 84951 | H21: 85351 | I21: 85751 | J21: 86151 | K21: 86551 | L21: 86951 | M21: 87351

Sheet ECTS 26-27
A1: Step | B1: Voc I | C1: Voc II | D1: M | E1: M+15
A2: 1 | B2: 0 | C2: 0 | D2: 0 | E2: 0
A3: 2 | B3: 45208 | C3: 45731 | D3: 46749 | E3: 47749
A4: 3 | B4: 45808 | C4: 46331 | D4: 47349 | E4: 48349
A5: 4 | B5: 46408 | C5: 46931 | D5: 47949 | E5: 48949
A6: 5 | B6: 47408 | C6: 47931 | D6: 48949 | E6: 49949
A7: 6 | B7: 48408 | C7: 48931 | D7: 49949 | E7: 50949
A8: 7 | B8: 49458 | C8: 49981 | D8: 50999 | E8: 51999
A9: 8 | B9: 50358 | C9: 50881 | D9: 51899 | E9: 52899
A10: 9 | B10: 51158 | C10: 51681 | D10: 52699 | E10: 53699
A11: 10 | B11: 52008 | C11: 52531 | D11: 53549 | E11: 54549
A12: 11 | B12: 52758 | C12: 53281 | D12: 54299 | E12: 55299
A13: 12 | B13: 53408 | C13: 53931 | D13: 54949 | E13: 55949
... A22: 21 | B22: 73574 | C22: 74846 | D22: 75615 | E22: 75715
A24: ECTS
A25: 6hrs50min | B25: 7:55-2:45 | E25: 7:45-3:15 would be median
A26: 185 days
A28: days | B28: 185
A29: min-per-day | B29: 410
A30: hours-per-day | B30: =B29/60 -> 6.8333333
A31: additional hours | B31: 16 | C31: 10 1hr monthly faculty meetings, 2hr OAC, 2hr Open House, 2hr student orientation
A32: total hours | B32: =(B28*B30)+B31 -> 1280.1667

Sheet Data
A1: First Column Comparisons
B2: Averages | E2: Minimum | H2: Maximum
A3: Step | B3: First Col Avg | C3: ECTS | D3: Difference | E3: First Col Min | F3: ECTS | G3: Difference | H3: First Col Max | I3: ECTS | J3: Difference
A4: 1 | B4: =AVERAGE('Crawford Central School 26-27'!D2, 'Corry 23-24'!C3,'Mercer 26-27'!B2,'Erie School District 26-27'!C2) -> 52685.25 | C4: 0 | E4: =MIN('Crawford Central School 26-27'!D2, 'Corry 23-24'!C3,'Mercer 26-27'!B2,'Erie School District 26-27'!C2) -> 42108 | F4: 0 | H4: =MAX('Crawford Central School 26-27'!D2, 'Corry 23-24'!C3,'Mercer 26-27'!B2,'Erie School District 26-27'!C2) -> 57646 | I4: 0 | K4: Notes:
A5: 2 | B5: =AVERAGE('Crawford Central School 26-27'!D3, 'Corry 23-24'!C4,'Mercer 26-27'!B3,'Erie School District 26-27'!C3) -> 53315.25 | C5: 45208 | D5: =C5 - B5 -> -8107.25 | E5: =MIN('Crawford Central School 26-27'!D3, 'Corry 23-24'!C4,'Mercer 26-27'!B3,'Erie School District 26-27'!C3) -> 42628 | F5: 45208 | G5: =F5 - E5 -> 2580 | H5: =MAX('Crawford Central School 26-27'!D3, 'Corry 23-24'!C4,'Mercer 26-27'!B3,'Erie School District 26-27'!C3) -> 59039 | I5: 45208 | J5: =I5 - H5 -> -13831 | K5: ECTS has the most steps of the 4 contracts (21), Mercer has the second most with 18.
A6: 3 | B6: =AVERAGE('Crawford Central School 26-27'!D4, 'Corry 23-24'!C5,'Mercer 26-27'!B4,'Erie School District 26-27'!C4) -> 53895.25 | C6: 45808 | D6: =C6 - B6 -> -8087.25 | E6: =MIN('Crawford Central School 26-27'!D4, 'Corry 23-24'!C5,'Mercer 26-27'!B4,'Erie School District 26-27'!C4) -> 42948 | F6: 45808 | G6: =F6 - E6 -> 2860 | H6: =MAX('Crawford Central School 26-27'!D4, 'Corry 23-24'!C5,'Mercer 26-27'!B4,'Erie School District 26-27'!C4) -> 60432 | I6: 45808 | J6: =I6 - H6 -> -14624 | K6: Tried to compare apples to apples by using the first column of each contract. Extended all contracts to 21 by repeating last step
A7: 4 | B7: =AVERAGE('Crawford Central School 26-27'!D5, 'Corry 23-24'!C6,'Mercer 26-27'!B5,'Erie School District 26-27'!C5) -> 54500.5 | C7: 46408 | D7: =C7 - B7 -> -8092.5 | E7: =MIN('Crawford Central School 26-27'!D5, 'Corry 23-24'!C6,'Mercer 26-27'!B5,'Erie School District 26-27'!C5) -> 43369 | F7: 46408 | G7: =F7 - E7 -> 3039 | H7: =MAX('Crawford Central School 26-27'!D5, 'Corry 23-24'!C6,'Mercer 26-27'!B5,'Erie School District 26-27'!C5) -> 61825 | I7: 46408 | J7: =I7 - H7 -> -15417
A8: 5 | B8: =AVERAGE('Crawford Central School 26-27'!D6, 'Corry 23-24'!C7,'Mercer 26-27'!B6,'Erie School District 26-27'!C6) -> 55400.5 | C8: 47408 | D8: =C8 - B8 -> -7992.5 | E8: =MIN('Crawford Central School 26-27'!D6, 'Corry 23-24'!C7,'Mercer 26-27'!B6,'Erie School District 26-27'!C6) -> 43824 | F8: 47408 | G8: =F8 - E8 -> 3584 | H8: =MAX('Crawford Central School 26-27'!D6, 'Corry 23-24'!C7,'Mercer 26-27'!B6,'Erie School District 26-27'!C6) -> 63218 | I8: 47408 | J8: =I8 - H8 -> -15810
A9: 6 | B9: =AVERAGE('Crawford Central School 26-27'!D7, 'Corry 23-24'!C8,'Mercer 26-27'!B7,'Erie School District 26-27'!C7) -> 56505.75 | C9: 48408 | D9: =C9 - B9 -> -8097.75 | E9: =MIN('Crawford Central School 26-27'!D7, 'Corry 23-24'!C8,'Mercer 26-27'!B7,'Erie School District 26-27'!C7) -> 45100 | F9: 48408 | G9: =F9 - E9 -> 3308 | H9: =MAX('Crawford Central School 26-27'!D7, 'Corry 23-24'!C8,'Mercer 26-27'!B7,'Erie School District 26-27'!C7) -> 64611 | I9: 48408 | J9: =I9 - H9 -> -16203
A10: 7 | B10: =AVERAGE('Crawford Central School 26-27'!D8, 'Corry 23-24'!C9,'Mercer 26-27'!B8,'Erie School District 26-27'!C8) -> 58218.5 | C10: 49458 | D10: =C10 - B10 -> -8760.5 | E10: =MIN('Crawford Central School 26-27'!D8, 'Corry 23-24'!C9,'Mercer 26-27'!B8,'Erie School District 26-27'!C8) -> 46603 | F10: 49458 | G10: =F10 - E10 -> 2855 | H10: =MAX('Crawford Central School 26-27'!D8, 'Corry 23-24'!C9,'Mercer 26-27'!B8,'Erie School District 26-27'!C8) -> 66004 | I10: 49458 | J10: =I10 - H10 -> -16546
A11: 8 | B11: =AVERAGE('Crawford Central School 26-27'!D9, 'Corry 23-24'!C10,'Mercer 26-27'!B9,'Erie School District 26-27'!C9) -> 58950.75 | C11: 50358 | D11: =C11 - B11 -> -8592.75 | E11: =MIN('Crawford Central School 26-27'!D9, 'Corry 23-24'!C10,'Mercer 26-27'!B9,'Erie School District 26-27'!C9) -> 48183 | F11: 50358 | G11: =F11 - E11 -> 2175 | H11: =MAX('Crawford Central School 26-27'!D9, 'Corry 23-24'!C10,'Mercer 26-27'!B9,'Erie School District 26-27'!C9) -> 67397 | I11: 50358 | J11: =I11 - H11 -> -17039
A12: 9 | B12: =AVERAGE('Crawford Central School 26-27'!D10, 'Corry 23-24'!C11,'Mercer 26-27'!B10,'Erie School District 26-27'!C10) -> 60200.75 | C12: 51158 | D12: =C12 - B12 -> -9042.75 | E12: =MIN('Crawford Central School 26-27'!D10, 'Corry 23-24'!C11,'Mercer 26-27'!B10,'Erie School District 26-27'!C10) -> 49836 | F12: 51158 | G12: =F12 - E12 -> 1322 | H12: =MAX('Crawford Central School 26-27'!D10, 'Corry 23-24'!C11,'Mercer 26-27'!B10,'Erie School District 26-27'!C10) -> 68790 | I12: 51158 | J12: =I12 - H12 -> -17632
A13: 10 | B13: =AVERAGE('Crawford Central School 26-27'!D11, 'Corry 23-24'!C12,'Mercer 26-27'!B11,'Erie School District 26-27'!C11) -> 62039.5 | C13: 52008 | D13: =C13 - B13 -> -10031.5 | E13: =MIN('Crawford Central School 26-27'!D11, 'Corry 23-24'!C12,'Mercer 26-27'!B11,'Erie School District 26-27'!C11) -> 51416 | F13: 52008 | G13: =F13 - E13 -> 592 | H13: =MAX('Crawford Central School 26-27'!D11, 'Corry 23-24'!C12,'Mercer 26-27'!B11,'Erie School District 26-27'!C11) -> 70183 | I13: 52008 | J13: =I13 - H13 -> -18175
A14: 11 | B14: =AVERAGE('Crawford Central School 26-27'!D12, 'Corry 23-24'!C13,'Mercer 26-27'!B12,'Erie School District 26-27'!C12) -> 63205.5 | C14: 52758 | D14: =C14 - B14 -> -10447.5 | E14: =MIN('Crawford Central School 26-27'!D12, 'Corry 23-24'!C13,'Mercer 26-27'!B12,'Erie School District 26-27'!C12) -> 52994 | F14: 52758 | G14: =F14 - E14 -> -236 | H14: =MAX('Crawford Central School 26-27'!D12, 'Corry 23-24'!C13,'Mercer 26-27'!B12,'Erie School District 26-27'!C12) -> 71576 | I14: 52758 | J14: =I14 - H14 -> -18818
A15: 12 | B15: =AVERAGE('Crawford Central School 26-27'!D13, 'Corry 23-24'!C14,'Mercer 26-27'!B13,'Erie School District 26-27'!C13) -> 64872 | C15: 53408 | D15: =C15 - B15 -> -11464 | E15: =MIN('Crawford Central School 26-27'!D13, 'Corry 23-24'!C14,'Mercer 26-27'!B13,'Erie School District 26-27'!C13) -> 54574 | F15: 53408 | G15: =F15 - E15 -> -1166 | H15: =MAX('Crawford Central School 26-27'!D13, 'Corry 23-24'!C14,'Mercer 26-27'!B13,'Erie School District 26-27'!C13) -> 72969 | I15: 53408 | J15: =I15 - H15 -> -19561
A16: 13 | B16: =AVERAGE('Crawford Central School 26-27'!D14, 'Corry 23-24'!C15,'Mercer 26-27'!B14,'Erie School District 26-27'!C14) -> 66537.75 | C16: 54158 | D16: =C16 - B16 -> -12379.75 | E16: =MIN('Crawford Central School 26-27'!D14, 'Corry 23-24'!C15,'Mercer 26-27'!B14,'Erie School District 26-27'!C14) -> 56152 | F16: 54158 | G16: =F16 - E16 -> -1994 | H16: =MAX('Crawford Central School 26-27'!D14, 'Corry 23-24'!C15,'Mercer 26-27'!B14,'Erie School District 26-27'!C14) -> 74362 | I16: 54158 | J16: =I16 - H16 -> -20204
A17: 14 | B17: =AVERAGE('Crawford Central School 26-27'!D15, 'Corry 23-24'!C16,'Mercer 26-27'!B15,'Erie School District 26-27'!C15) -> 68204.25 | C17: 55158 | D17: =C17 - B17 -> -13046.25 | E17: =MIN('Crawford Central School 26-27'!D15, 'Corry 23-24'!C16,'Mercer 26-27'!B15,'Erie School District 26-27'!C15) -> 57732 | F17: 55158 | G17: =F17 - E17 -> -2574 | H17: =MAX('Crawford Central School 26-27'!D15, 'Corry 23-24'!C16,'Mercer 26-27'!B15,'Erie School District 26-27'!C15) -> 75755 | I17: 55158 | J17: =I17 - H17 -> -20597
A18: 15 | B18: =AVERAGE('Crawford Central School 26-27'!D16, 'Corry 23-24'!C17,'Mercer 26-27'!B16,'Erie School District 26-27'!C16) -> 69346 | C18: 56458 | D18: =C18 - B18 -> -12888 | E18: =MIN('Crawford Central School 26-27'!D16, 'Corry 23-24'!C17,'Mercer 26-27'!B16,'Erie School District 26-27'!C16) -> 59454 | F18: 56458 | G18: =F18 - E18 -> -2996 | H18: =MAX('Crawford Central School 26-27'!D16, 'Corry 23-24'!C17,'Mercer 26-27'!B16,'Erie School District 26-27'!C16) -> 77148 | I18: 56458 | J18: =I18 - H18 -> -20690
... A24: 21 | B24: =AVERAGE('Crawford Central School 26-27'!D22, 'Corry 23-24'!C23,'Mercer 26-27'!B22,'Erie School District 26-27'!C22) -> 70958 | C24: 73574 | D24: =C24 - B24 -> 2616 | E24: =MIN('Crawford Central School 26-27'!D22, 'Corry 23-24'!C23,'Mercer 26-27'!B22,'Erie School District 26-27'!C22) -> 61547 | F24: 73574 | G24: =F24 - E24 -> 12027 | H24: =MAX('Crawford Central School 26-27'!D22, 'Corry 23-24'!C23,'Mercer 26-27'!B22,'Erie School District 26-27'!C22) -> 77996 | I24: 73574 | J24: =I24 - H24 -> -4422
A26: Masters Comparison
B27: Averages | E27: Minimum | H27: Maximum
A28: Step | B28: Masters Avg | C28: ECTS | D28: Difference | E28: Masters Min | F28: ECTS | G28: Difference | H28: Masters Max | I28: ECTS | J28: Difference
A29: 1 | B29: =AVERAGE('Crawford Central School 26-27'!F2, 'Corry 23-24'!G3,'Mercer 26-27'!C2,'Erie School District 26-27'!I2) -> 58006.25 | C29: 0 | E29: =MIN('Crawford Central School 26-27'!F2, 'Corry 23-24'!G3,'Mercer 26-27'!C2,'Erie School District 26-27'!I2) -> 50240 | F29: 0 | H29: =MAX('Crawford Central School 26-27'!F2, 'Corry 23-24'!G3,'Mercer 26-27'!C2,'Erie School District 26-27'!I2) -> 61949 | I29: 0
A30: 2 | B30: =AVERAGE('Crawford Central School 26-27'!F3, 'Corry 23-24'!G4,'Mercer 26-27'!C3,'Erie School District 26-27'!I3) -> 58669.25 | C30: 46749 | D30: =C30 - B30 -> -11920.25 | E30: =MIN('Crawford Central School 26-27'!F3, 'Corry 23-24'!G4,'Mercer 26-27'!C3,'Erie School District 26-27'!I3) -> 50705 | F30: 46749 | G30: =F30 - E30 -> -3956 | H30: =MAX('Crawford Central School 26-27'!F3, 'Corry 23-24'!G4,'Mercer 26-27'!C3,'Erie School District 26-27'!I3) -> 63529 | I30: 46749 | J30: =I30 - H30 -> -16780
A31: 3 | B31: =AVERAGE('Crawford Central School 26-27'!F4, 'Corry 23-24'!G5,'Mercer 26-27'!C4,'Erie School District 26-27'!I4) -> 59328.75 | C31: 47349 | D31: =C31 - B31 -> -11979.75 | E31: =MIN('Crawford Central School 26-27'!F4, 'Corry 23-24'!G5,'Mercer 26-27'!C4,'Erie School District 26-27'!I4) -> 51156 | F31: 47349 | G31: =F31 - E31 -> -3807 | H31: =MAX('Crawford Central School 26-27'!F4, 'Corry 23-24'!G5,'Mercer 26-27'!C4,'Erie School District 26-27'!I4) -> 65109 | I31: 47349 | J31: =I31 - H31 -> -17760
A32: 4 | B32: =AVERAGE('Crawford Central School 26-27'!F5, 'Corry 23-24'!G6,'Mercer 26-27'!C5,'Erie School District 26-27'!I5) -> 60001.75 | C32: 47949 | D32: =C32 - B32 -> -12052.75 | E32: =MIN('Crawford Central School 26-27'!F5, 'Corry 23-24'!G6,'Mercer 26-27'!C5,'Erie School District 26-27'!I5) -> 51661 | F32: 47949 | G32: =F32 - E32 -> -3712 | H32: =MAX('Crawford Central School 26-27'!F5, 'Corry 23-24'!G6,'Mercer 26-27'!C5,'Erie School District 26-27'!I5) -> 66689 | I32: 47949 | J32: =I32 - H32 -> -18740
A33: 5 | B33: =AVERAGE('Crawford Central School 26-27'!F6, 'Corry 23-24'!G7,'Mercer 26-27'!C6,'Erie School District 26-27'!I6) -> 60948.5 | C33: 48949 | D33: =C33 - B33 -> -11999.5 | E33: =MIN('Crawford Central School 26-27'!F6, 'Corry 23-24'!G7,'Mercer 26-27'!C6,'Erie School District 26-27'!I6) -> 52116 | F33: 48949 | G33: =F33 - E33 -> -3167 | H33: =MAX('Crawford Central School 26-27'!F6, 'Corry 23-24'!G7,'Mercer 26-27'!C6,'Erie School District 26-27'!I6) -> 68269 | I33: 48949 | J33: =I33 - H33 -> -19320
A34: 6 | B34: =AVERAGE('Crawford Central School 26-27'!F7, 'Corry 23-24'!G8,'Mercer 26-27'!C7,'Erie School District 26-27'!I7) -> 62144.25 | C34: 49949 | D34: =C34 - B34 -> -12195.25 | E34: =MIN('Crawford Central School 26-27'!F7, 'Corry 23-24'!G8,'Mercer 26-27'!C7,'Erie School District 26-27'!I7) -> 53567 | F34: 49949 | G34: =F34 - E34 -> -3618 | H34: =MAX('Crawford Central School 26-27'!F7, 'Corry 23-24'!G8,'Mercer 26-27'!C7,'Erie School District 26-27'!I7) -> 69849 | I34: 49949 | J34: =I34 - H34 -> -19900
A35: 7 | B35: =AVERAGE('Crawford Central School 26-27'!F8, 'Corry 23-24'!G9,'Mercer 26-27'!C8,'Erie School District 26-27'!I8) -> 63515.25 | C35: 50999 | D35: =C35 - B35 -> -12516.25 | E35: =MIN('Crawford Central School 26-27'!F8, 'Corry 23-24'!G9,'Mercer 26-27'!C8,'Erie School District 26-27'!I8) -> 55070 | F35: 50999 | G35: =F35 - E35 -> -4071 | H35: =MAX('Crawford Central School 26-27'!F8, 'Corry 23-24'!G9,'Mercer 26-27'!C8,'Erie School District 26-27'!I8) -> 71429 | I35: 50999 | J35: =I35 - H35 -> -20430
A36: 8 | B36: =AVERAGE('Crawford Central School 26-27'!F9, 'Corry 23-24'!G10,'Mercer 26-27'!C9,'Erie School District 26-27'!I9) -> 64902 | C36: 51899 | D36: =C36 - B36 -> -13003 | E36: =MIN('Crawford Central School 26-27'!F9, 'Corry 23-24'!G10,'Mercer 26-27'!C9,'Erie School District 26-27'!I9) -> 56650 | F36: 51899 | G36: =F36 - E36 -> -4751 | H36: =MAX('Crawford Central School 26-27'!F9, 'Corry 23-24'!G10,'Mercer 26-27'!C9,'Erie School District 26-27'!I9) -> 73009 | I36: 51899 | J36: =I36 - H36 -> -21110
A37: 9 | B37: =AVERAGE('Crawford Central School 26-27'!F10, 'Corry 23-24'!G11,'Mercer 26-27'!C10,'Erie School District 26-27'!I10) -> 66307.5 | C37: 52699 | D37: =C37 - B37 -> -13608.5 | E37: =MIN('Crawford Central School 26-27'!F10, 'Corry 23-24'!G11,'Mercer 26-27'!C10,'Erie School District 26-27'!I10) -> 58304 | F37: 52699 | G37: =F37 - E37 -> -5605 | H37: =MAX('Crawford Central School 26-27'!F10, 'Corry 23-24'!G11,'Mercer 26-27'!C10,'Erie School District 26-27'!I10) -> 74589 | I37: 52699 | J37: =I37 - H37 -> -21890
A38: 10 | B38: =AVERAGE('Crawford Central School 26-27'!F11, 'Corry 23-24'!G12,'Mercer 26-27'!C11,'Erie School District 26-27'!I11) -> 67692.75 | C38: 53549 | D38: =C38 - B38 -> -14143.75 | E38: =MIN('Crawford Central School 26-27'!F11, 'Corry 23-24'!G12,'Mercer 26-27'!C11,'Erie School District 26-27'!I11) -> 59883 | F38: 53549 | G38: =F38 - E38 -> -6334 | H38: =MAX('Crawford Central School 26-27'!F11, 'Corry 23-24'!G12,'Mercer 26-27'!C11,'Erie School District 26-27'!I11) -> 76169 | I38: 53549 | J38: =I38 - H38 -> -22620
A39: 11 | B39: =AVERAGE('Crawford Central School 26-27'!F12, 'Corry 23-24'!G13,'Mercer 26-27'!C12,'Erie School District 26-27'!I12) -> 69430.75 | C39: 54299 | D39: =C39 - B39 -> -15131.75 | E39: =MIN('Crawford Central School 26-27'!F12, 'Corry 23-24'!G13,'Mercer 26-27'!C12,'Erie School District 26-27'!I12) -> 61462 | F39: 54299 | G39: =F39 - E39 -> -7163 | H39: =MAX('Crawford Central School 26-27'!F12, 'Corry 23-24'!G13,'Mercer 26-27'!C12,'Erie School District 26-27'!I12) -> 77749 | I39: 54299 | J39: =I39 - H39 -> -23450
A40: 12 | B40: =AVERAGE('Crawford Central School 26-27'!F13, 'Corry 23-24'!G14,'Mercer 26-27'!C13,'Erie School District 26-27'!I13) -> 71118.5 | C40: 54949 | D40: =C40 - B40 -> -16169.5 | E40: =MIN('Crawford Central School 26-27'!F13, 'Corry 23-24'!G14,'Mercer 26-27'!C13,'Erie School District 26-27'!I13) -> 63041 | F40: 54949 | G40: =F40 - E40 -> -8092 | H40: =MAX('Crawford Central School 26-27'!F13, 'Corry 23-24'!G14,'Mercer 26-27'!C13,'Erie School District 26-27'!I13) -> 79329 | I40: 54949 | J40: =I40 - H40 -> -24380
A41: 13 | B41: =AVERAGE('Crawford Central School 26-27'!F14, 'Corry 23-24'!G15,'Mercer 26-27'!C14,'Erie School District 26-27'!I14) -> 72831.5 | C41: 55699 | D41: =C41 - B41 -> -17132.5 | E41: =MIN('Crawford Central School 26-27'!F14, 'Corry 23-24'!G15,'Mercer 26-27'!C14,'Erie School District 26-27'!I14) -> 64620 | F41: 55699 | G41: =F41 - E41 -> -8921 | H41: =MAX('Crawford Central School 26-27'!F14, 'Corry 23-24'!G15,'Mercer 26-27'!C14,'Erie School District 26-27'!I14) -> 80909 | I41: 55699 | J41: =I41 - H41 -> -25210
... A49: 21 | B49: =AVERAGE('Crawford Central School 26-27'!F22, 'Corry 23-24'!G23,'Mercer 26-27'!C22,'Erie School District 26-27'!I22) -> 77701.5 | C49: 75615 | D49: =C49 - B49 -> -2086.5 | E49: =MIN('Crawford Central School 26-27'!F22, 'Corry 23-24'!G23,'Mercer 26-27'!C22,'Erie School District 26-27'!I22) -> 70440 | F49: 75615 | G49: =F49 - E49 -> 5175 | H49: =MAX('Crawford Central School 26-27'!F22, 'Corry 23-24'!G23,'Mercer 26-27'!C22,'Erie School District 26-27'!I22) -> 84069 | I49: 75615 | J49: =I49 - H49 -> -8454
A51: Masters + 15
B52: Averages | E52: Minimum | H52: Maximum
A53: Step | B53: M+15 Avg | C53: ECTS | D53: Difference | E53: M+15 Min | F53: ECTS | G53: Difference | H53: M+15 Max | I53: ECTS | J53: Difference
A54: 1 | B54: =AVERAGE('Crawford Central School 26-27'!G2, 'Corry 23-24'!H3,'Mercer 26-27'!D2,'Erie School District 26-27'!L2) -> 60101.75 | C54: 0 | E54: =MIN('Crawford Central School 26-27'!G2, 'Corry 23-24'!H3,'Mercer 26-27'!D2,'Erie School District 26-27'!L2) -> 51540 | F54: 0 | H54: =MAX('Crawford Central School 26-27'!G2, 'Corry 23-24'!H3,'Mercer 26-27'!D2,'Erie School District 26-27'!L2) -> 64538 | I54: 0
...

Sheet Data- With Avg Workday Adjustme
A1: This sheet is similar to the regular data sheet, but it has an adjusted difference based on the average of how many hours ECTS works compared to the other schools
A3: Estimated Contract Hours Difference
A4: Modifier is how many hours per year we are required to work compared to other schools
A5: Crawford | B5: ECTS | C5: Modifier | D5: Corry | E5: ECTS | F5: Modifier | G5: Mercer | H5: ECTS | I5: Modifier | J5: ESD | K5: ECTS | L5: Modifier
A6: ='Crawford Central School 26-27'!B35 -> 1393.5 | B6: ='ECTS 26-27'!B32 -> 1280.1667 | C6: =B6/A6 -> 0.91867002 | D6: ='Corry 23-24'!B33 -> 1387.5 | E6: ='ECTS 26-27'!B32 -> 1280.1667 | F6: =E6/D6 -> 0.92264264 | G6: ='Mercer 26-27'!B32 -> 1387.5 | H6: ='ECTS 26-27'!B32 -> 1280.1667 | I6: =H6/G6 -> 0.92264264 | J6: ='Erie School District 26-27'!B33 -> 1325.8333 | K6: ='ECTS 26-27'!B32 -> 1280.1667 | L6: =K6/J6 -> 0.96555625
A8: Modifier Adjustment | B8: =AVERAGE(C6,F6,I6,L6) -> 0.93237789 | C8: This means ECTS works about 56 minutes for everyone else's hour
A10: First Column Comparisons
B11: Averages | E11: Minimum | H11: Maximum
A12: Step | B12: Avg Adjusted | C12: ECTS | D12: Difference | E12: Min Adjusted | F12: ECTS | G12: Difference | H12: Max Adjusted | I12: ECTS | J12: Difference
A13: 1 | B13: =AVERAGE('Crawford Central School 26-27'!D2, 'Corry 23-24'!C3,'Mercer 26-27'!B2,'Erie School District 26-27'!C2)*$B$8 -> 49122.562 | C13: 0 | E13: =MIN('Crawford Central School 26-27'!D2, 'Corry 23-24'!C3,'Mercer 26-27'!B2,'Erie School District 26-27'!C2) * $B$8 -> 39260.568 | F13: 0 | H13: =MAX('Crawford Central School 26-27'!D2, 'Corry 23-24'!C3,'Mercer 26-27'!B2,'Erie School District 26-27'!C2) * $B$8 -> 53747.856 | I13: 0 | K13: Notes:
A14: 2 | B14: =AVERAGE('Crawford Central School 26-27'!D3, 'Corry 23-24'!C4,'Mercer 26-27'!B3,'Erie School District 26-27'!C3)*$B$8 -> 49709.96 | C14: 45208 | D14: =C14 - B14 -> -4501.9602 | E14: =MIN('Crawford Central School 26-27'!D3, 'Corry 23-24'!C4,'Mercer 26-27'!B3,'Erie School District 26-27'!C3) * $B$8 -> 39745.405 | F14: 45208 | G14: =F14 - E14 -> 5462.5954 | H14: =MAX('Crawford Central School 26-27'!D3, 'Corry 23-24'!C4,'Mercer 26-27'!B3,'Erie School District 26-27'!C3) * $B$8 -> 55046.658 | I14: 45208 | J14: =I14 - H14 -> -9838.6582 | K14: ECTS has the most steps of the 4 contracts (21), Mercer has the second most with 18.
A15: 3 | B15: =AVERAGE('Crawford Central School 26-27'!D4, 'Corry 23-24'!C5,'Mercer 26-27'!B4,'Erie School District 26-27'!C4)*$B$8 -> 50250.739 | C15: 45808 | D15: =C15 - B15 -> -4442.7394 | E15: =MIN('Crawford Central School 26-27'!D4, 'Corry 23-24'!C5,'Mercer 26-27'!B4,'Erie School District 26-27'!C4) * $B$8 -> 40043.766 | F15: 45808 | G15: =F15 - E15 -> 5764.2344 | H15: =MAX('Crawford Central School 26-27'!D4, 'Corry 23-24'!C5,'Mercer 26-27'!B4,'Erie School District 26-27'!C4) * $B$8 -> 56345.461 | I15: 45808 | J15: =I15 - H15 -> -10537.461 | K15: Tried to compare apples to apples by using the first column of each contract. Extended all contracts to 21 by repeating last step
A16: 4 | B16: =AVERAGE('Crawford Central School 26-27'!D5, 'Corry 23-24'!C6,'Mercer 26-27'!B5,'Erie School District 26-27'!C5)*$B$8 -> 50815.061 | C16: 46408 | D16: =C16 - B16 -> -4407.0611 | E16: =MIN('Crawford Central School 26-27'!D5, 'Corry 23-24'!C6,'Mercer 26-27'!B5,'Erie School District 26-27'!C5) * $B$8 -> 40436.297 | F16: 46408 | G16: =F16 - E16 -> 5971.7033 | H16: =MAX('Crawford Central School 26-27'!D5, 'Corry 23-24'!C6,'Mercer 26-27'!B5,'Erie School District 26-27'!C5) * $B$8 -> 57644.263 | I16: 46408 | J16: =I16 - H16 -> -11236.263
A17: 5 | B17: =AVERAGE('Crawford Central School 26-27'!D6, 'Corry 23-24'!C7,'Mercer 26-27'!B6,'Erie School District 26-27'!C6)*$B$8 -> 51654.201 | C17: 47408 | D17: =C17 - B17 -> -4246.2012 | E17: =MIN('Crawford Central School 26-27'!D6, 'Corry 23-24'!C7,'Mercer 26-27'!B6,'Erie School District 26-27'!C6) * $B$8 -> 40860.529 | F17: 47408 | G17: =F17 - E17 -> 6547.4714 | H17: =MAX('Crawford Central School 26-27'!D6, 'Corry 23-24'!C7,'Mercer 26-27'!B6,'Erie School District 26-27'!C6) * $B$8 -> 58943.065 | I17: 47408 | J17: =I17 - H17 -> -11535.065
A18: 6 | B18: =AVERAGE('Crawford Central School 26-27'!D7, 'Corry 23-24'!C8,'Mercer 26-27'!B7,'Erie School District 26-27'!C7)*$B$8 -> 52684.712 | C18: 48408 | D18: =C18 - B18 -> -4276.7119 | E18: =MIN('Crawford Central School 26-27'!D7, 'Corry 23-24'!C8,'Mercer 26-27'!B7,'Erie School District 26-27'!C7) * $B$8 -> 42050.243 | F18: 48408 | G18: =F18 - E18 -> 6357.7572 | H18: =MAX('Crawford Central School 26-27'!D7, 'Corry 23-24'!C8,'Mercer 26-27'!B7,'Erie School District 26-27'!C7) * $B$8 -> 60241.868 | I18: 48408 | J18: =I18 - H18 -> -11833.868
A19: 7 | B19: =AVERAGE('Crawford Central School 26-27'!D8, 'Corry 23-24'!C9,'Mercer 26-27'!B8,'Erie School District 26-27'!C8)*$B$8 -> 54281.642 | C19: 49458 | D19: =C19 - B19 -> -4823.6421 | E19: =MIN('Crawford Central School 26-27'!D8, 'Corry 23-24'!C9,'Mercer 26-27'!B8,'Erie School District 26-27'!C8) * $B$8 -> 43451.607 | F19: 49458 | G19: =F19 - E19 -> 6006.3933 | H19: =MAX('Crawford Central School 26-27'!D8, 'Corry 23-24'!C9,'Mercer 26-27'!B8,'Erie School District 26-27'!C8) * $B$8 -> 61540.67 | I19: 49458 | J19: =I19 - H19 -> -12082.67
A20: 8 | B20: =AVERAGE('Crawford Central School 26-27'!D9, 'Corry 23-24'!C10,'Mercer 26-27'!B9,'Erie School District 26-27'!C9)*$B$8 -> 54964.376 | C20: 50358 | D20: =C20 - B20 -> -4606.3758 | E20: =MIN('Crawford Central School 26-27'!D9, 'Corry 23-24'!C10,'Mercer 26-27'!B9,'Erie School District 26-27'!C9) * $B$8 -> 44924.764 | F20: 50358 | G20: =F20 - E20 -> 5433.2362 | H20: =MAX('Crawford Central School 26-27'!D9, 'Corry 23-24'!C10,'Mercer 26-27'!B9,'Erie School District 26-27'!C9) * $B$8 -> 62839.473 | I20: 50358 | J20: =I20 - H20 -> -12481.473
A21: 9 | B21: =AVERAGE('Crawford Central School 26-27'!D10, 'Corry 23-24'!C11,'Mercer 26-27'!B10,'Erie School District 26-27'!C10)*$B$8 -> 56129.848 | C21: 51158 | D21: =C21 - B21 -> -4971.8482 | E21: =MIN('Crawford Central School 26-27'!D10, 'Corry 23-24'!C11,'Mercer 26-27'!B10,'Erie School District 26-27'!C10) * $B$8 -> 46465.984 | F21: 51158 | G21: =F21 - E21 -> 4692.0155 | H21: =MAX('Crawford Central School 26-27'!D10, 'Corry 23-24'!C11,'Mercer 26-27'!B10,'Erie School District 26-27'!C10) * $B$8 -> 64138.275 | I21: 51158 | J21: =I21 - H21 -> -12980.275
A22: 10 | B22: =AVERAGE('Crawford Central School 26-27'!D11, 'Corry 23-24'!C12,'Mercer 26-27'!B11,'Erie School District 26-27'!C11)*$B$8 -> 57844.258 | C22: 52008 | D22: =C22 - B22 -> -5836.258 | E22: =MIN('Crawford Central School 26-27'!D11, 'Corry 23-24'!C12,'Mercer 26-27'!B11,'Erie School District 26-27'!C11) * $B$8 -> 47939.142 | F22: 52008 | G22: =F22 - E22 -> 4068.8585 | H22: =MAX('Crawford Central School 26-27'!D11, 'Corry 23-24'!C12,'Mercer 26-27'!B11,'Erie School District 26-27'!C11) * $B$8 -> 65437.077 | I22: 52008 | J22: =I22 - H22 -> -13429.077
A23: 11 | B23: =AVERAGE('Crawford Central School 26-27'!D12, 'Corry 23-24'!C13,'Mercer 26-27'!B12,'Erie School District 26-27'!C12)*$B$8 -> 58931.411 | C23: 52758 | D23: =C23 - B23 -> -6173.4106 | E23: =MIN('Crawford Central School 26-27'!D12, 'Corry 23-24'!C13,'Mercer 26-27'!B12,'Erie School District 26-27'!C12) * $B$8 -> 49410.434 | F23: 52758 | G23: =F23 - E23 -> 3347.5662 | H23: =MAX('Crawford Central School 26-27'!D12, 'Corry 23-24'!C13,'Mercer 26-27'!B12,'Erie School District 26-27'!C12) * $B$8 -> 66735.88 | I23: 52758 | J23: =I23 - H23 -> -13977.88
A24: 12 | B24: =AVERAGE('Crawford Central School 26-27'!D13, 'Corry 23-24'!C14,'Mercer 26-27'!B13,'Erie School District 26-27'!C13)*$B$8 -> 60485.218 | C24: 53408 | D24: =C24 - B24 -> -7077.2184 | E24: =MIN('Crawford Central School 26-27'!D13, 'Corry 23-24'!C14,'Mercer 26-27'!B13,'Erie School District 26-27'!C13) * $B$8 -> 50883.591 | F24: 53408 | G24: =F24 - E24 -> 2524.4091 | H24: =MAX('Crawford Central School 26-27'!D13, 'Corry 23-24'!C14,'Mercer 26-27'!B13,'Erie School District 26-27'!C13) * $B$8 -> 68034.682 | I24: 53408 | J24: =I24 - H24 -> -14626.682
A25: 13 | B25: =AVERAGE('Crawford Central School 26-27'!D14, 'Corry 23-24'!C15,'Mercer 26-27'!B14,'Erie School District 26-27'!C14)*$B$8 -> 62038.327 | C25: 54158 | D25: =C25 - B25 -> -7880.3269 | E25: =MIN('Crawford Central School 26-27'!D14, 'Corry 23-24'!C15,'Mercer 26-27'!B14,'Erie School District 26-27'!C14) * $B$8 -> 52354.883 | F25: 54158 | G25: =F25 - E25 -> 1803.1168 | H25: =MAX('Crawford Central School 26-27'!D14, 'Corry 23-24'!C15,'Mercer 26-27'!B14,'Erie School District 26-27'!C14) * $B$8 -> 69333.485 | I25: 54158 | J25: =I25 - H25 -> -15175.485
A26: 14 | B26: =AVERAGE('Crawford Central School 26-27'!D15, 'Corry 23-24'!C16,'Mercer 26-27'!B15,'Erie School District 26-27'!C15)*$B$8 -> 63592.135 | C26: 55158 | D26: =C26 - B26 -> -8434.1346 | E26: =MIN('Crawford Central School 26-27'!D15, 'Corry 23-24'!C16,'Mercer 26-27'!B15,'Erie School District 26-27'!C15) * $B$8 -> 53828.04 | F26: 55158 | G26: =F26 - E26 -> 1329.9597 | H26: =MAX('Crawford Central School 26-27'!D15, 'Corry 23-24'!C16,'Mercer 26-27'!B15,'Erie School District 26-27'!C15) * $B$8 -> 70632.287 | I26: 55158 | J26: =I26 - H26 -> -15474.287
A27: 15 | B27: =AVERAGE('Crawford Central School 26-27'!D16, 'Corry 23-24'!C17,'Mercer 26-27'!B16,'Erie School District 26-27'!C16)*$B$8 -> 64656.677 | C27: 56458 | D27: =C27 - B27 -> -8198.6771 | E27: =MIN('Crawford Central School 26-27'!D16, 'Corry 23-24'!C17,'Mercer 26-27'!B16,'Erie School District 26-27'!C16) * $B$8 -> 55433.595 | F27: 56458 | G27: =F27 - E27 -> 1024.405 | H27: =MAX('Crawford Central School 26-27'!D16, 'Corry 23-24'!C17,'Mercer 26-27'!B16,'Erie School District 26-27'!C16) * $B$8 -> 71931.089 | I27: 56458 | J27: =I27 - H27 -> -15473.089
... A33: 21 | B33: =AVERAGE('Crawford Central School 26-27'!D22, 'Corry 23-24'!C23,'Mercer 26-27'!B22,'Erie School District 26-27'!C22)*$B$8 -> 66159.67 | C33: 73574 | D33: =C33 - B33 -> 7414.3298 | E33: =MIN('Crawford Central School 26-27'!D22, 'Corry 23-24'!C23,'Mercer 26-27'!B22,'Erie School District 26-27'!C22) * $B$8 -> 57385.062 | F33: 73574 | G33: =F33 - E33 -> 16188.938 | H33: =MAX('Crawford Central School 26-27'!D22, 'Corry 23-24'!C23,'Mercer 26-27'!B22,'Erie School District 26-27'!C22) * $B$8 -> 72721.746 | I33: 73574 | J33: =I33 - H33 -> 852.25419
A35: Masters Comparison
B36: Averages | E36: Minimum | H36: Maximum
A37: Step | B37: Avg Adjusted | C37: ECTS | D37: Difference | E37: Min Adjusted | F37: ECTS | G37: Difference | H37: Max Adjusted | I37: ECTS | J37: Difference
A38: 1 | B38: =AVERAGE('Crawford Central School 26-27'!F2, 'Corry 23-24'!G3,'Mercer 26-27'!C2,'Erie School District 26-27'!I2) * $B$8 -> 54083.745 | C38: 0 | E38: =MIN('Crawford Central School 26-27'!F2, 'Corry 23-24'!G3,'Mercer 26-27'!C2,'Erie School District 26-27'!I2) * $B$8 -> 46842.665 | F38: 0 | H38: =MAX('Crawford Central School 26-27'!F2, 'Corry 23-24'!G3,'Mercer 26-27'!C2,'Erie School District 26-27'!I2) * $B$8 -> 57759.878 | I38: 0
A39: 2 | B39: =AVERAGE('Crawford Central School 26-27'!F3, 'Corry 23-24'!G4,'Mercer 26-27'!C3,'Erie School District 26-27'!I3) * $B$8 -> 54701.911 | C39: 46749 | D39: =C39 - B39 -> -7952.9114 | E39: =MIN('Crawford Central School 26-27'!F3, 'Corry 23-24'!G4,'Mercer 26-27'!C3,'Erie School District 26-27'!I3) * $B$8 -> 47276.221 | F39: 46749 | G39: =F39 - E39 -> -527.22085 | H39: =MAX('Crawford Central School 26-27'!F3, 'Corry 23-24'!G4,'Mercer 26-27'!C3,'Erie School District 26-27'!I3) * $B$8 -> 59233.035 | I39: 46749 | J39: =I39 - H39 -> -12484.035
A40: 3 | B40: =AVERAGE('Crawford Central School 26-27'!F4, 'Corry 23-24'!G5,'Mercer 26-27'!C4,'Erie School District 26-27'!I4) * $B$8 -> 55316.815 | C40: 47349 | D40: =C40 - B40 -> -7967.8147 | E40: =MIN('Crawford Central School 26-27'!F4, 'Corry 23-24'!G5,'Mercer 26-27'!C4,'Erie School District 26-27'!I4) * $B$8 -> 47696.723 | F40: 47349 | G40: =F40 - E40 -> -347.72327 | H40: =MAX('Crawford Central School 26-27'!F4, 'Corry 23-24'!G5,'Mercer 26-27'!C4,'Erie School District 26-27'!I4) * $B$8 -> 60706.192 | I40: 47349 | J40: =I40 - H40 -> -13357.192
A41: 4 | B41: =AVERAGE('Crawford Central School 26-27'!F5, 'Corry 23-24'!G6,'Mercer 26-27'!C5,'Erie School District 26-27'!I5) * $B$8 -> 55944.305 | C41: 47949 | D41: =C41 - B41 -> -7995.305 | E41: =MIN('Crawford Central School 26-27'!F5, 'Corry 23-24'!G6,'Mercer 26-27'!C5,'Erie School District 26-27'!I5) * $B$8 -> 48167.574 | F41: 47949 | G41: =F41 - E41 -> -218.57411 | H41: =MAX('Crawford Central School 26-27'!F5, 'Corry 23-24'!G6,'Mercer 26-27'!C5,'Erie School District 26-27'!I5) * $B$8 -> 62179.349 | I41: 47949 | J41: =I41 - H41 -> -14230.349
A42: 5 | B42: =AVERAGE('Crawford Central School 26-27'!F6, 'Corry 23-24'!G7,'Mercer 26-27'!C6,'Erie School District 26-27'!I6) * $B$8 -> 56827.034 | C42: 48949 | D42: =C42 - B42 -> -7878.0337 | E42: =MIN('Crawford Central School 26-27'!F6, 'Corry 23-24'!G7,'Mercer 26-27'!C6,'Erie School District 26-27'!I6) * $B$8 -> 48591.806 | F42: 48949 | G42: =F42 - E42 -> 357.19395 | H42: =MAX('Crawford Central School 26-27'!F6, 'Corry 23-24'!G7,'Mercer 26-27'!C6,'Erie School District 26-27'!I6) * $B$8 -> 63652.506 | I42: 48949 | J42: =I42 - H42 -> -14703.506
A43: 6 | B43: =AVERAGE('Crawford Central School 26-27'!F7, 'Corry 23-24'!G8,'Mercer 26-27'!C7,'Erie School District 26-27'!I7) * $B$8 -> 57941.925 | C43: 49949 | D43: =C43 - B43 -> -7992.9246 | E43: =MIN('Crawford Central School 26-27'!F7, 'Corry 23-24'!G8,'Mercer 26-27'!C7,'Erie School District 26-27'!I7) * $B$8 -> 49944.686 | F43: 49949 | G43: =F43 - E43 -> 4.3136365 | H43: =MAX('Crawford Central School 26-27'!F7, 'Corry 23-24'!G8,'Mercer 26-27'!C7,'Erie School District 26-27'!I7) * $B$8 -> 65125.663 | I43: 49949 | J43: =I43 - H43 -> -15176.663
A44: 7 | B44: =AVERAGE('Crawford Central School 26-27'!F8, 'Corry 23-24'!G9,'Mercer 26-27'!C8,'Erie School District 26-27'!I8) * $B$8 -> 59220.215 | C44: 50999 | D44: =C44 - B44 -> -8221.2147 | E44: =MIN('Crawford Central School 26-27'!F8, 'Corry 23-24'!G9,'Mercer 26-27'!C8,'Erie School District 26-27'!I8) * $B$8 -> 51346.05 | F44: 50999 | G44: =F44 - E44 -> -347.05033 | H44: =MAX('Crawford Central School 26-27'!F8, 'Corry 23-24'!G9,'Mercer 26-27'!C8,'Erie School District 26-27'!I8) * $B$8 -> 66598.82 | I44: 50999 | J44: =I44 - H44 -> -15599.82
A45: 8 | B45: =AVERAGE('Crawford Central School 26-27'!F9, 'Corry 23-24'!G10,'Mercer 26-27'!C9,'Erie School District 26-27'!I9) * $B$8 -> 60513.19 | C45: 51899 | D45: =C45 - B45 -> -8614.1897 | E45: =MIN('Crawford Central School 26-27'!F9, 'Corry 23-24'!G10,'Mercer 26-27'!C9,'Erie School District 26-27'!I9) * $B$8 -> 52819.207 | F45: 51899 | G45: =F45 - E45 -> -920.20739 | H45: =MAX('Crawford Central School 26-27'!F9, 'Corry 23-24'!G10,'Mercer 26-27'!C9,'Erie School District 26-27'!I9) * $B$8 -> 68071.977 | I45: 51899 | J45: =I45 - H45 -> -16172.977
A46: 9 | B46: =AVERAGE('Crawford Central School 26-27'!F10, 'Corry 23-24'!G11,'Mercer 26-27'!C10,'Erie School District 26-27'!I10) * $B$8 -> 61823.647 | C46: 52699 | D46: =C46 - B46 -> -9124.6469 | E46: =MIN('Crawford Central School 26-27'!F10, 'Corry 23-24'!G11,'Mercer 26-27'!C10,'Erie School District 26-27'!I10) * $B$8 -> 54361.36 | F46: 52699 | G46: =F46 - E46 -> -1662.3604 | H46: =MAX('Crawford Central School 26-27'!F10, 'Corry 23-24'!G11,'Mercer 26-27'!C10,'Erie School District 26-27'!I10) * $B$8 -> 69545.134 | I46: 52699 | J46: =I46 - H46 -> -16846.134
A47: 10 | B47: =AVERAGE('Crawford Central School 26-27'!F11, 'Corry 23-24'!G12,'Mercer 26-27'!C11,'Erie School District 26-27'!I11) * $B$8 -> 63115.223 | C47: 53549 | D47: =C47 - B47 -> -9566.2233 | E47: =MIN('Crawford Central School 26-27'!F11, 'Corry 23-24'!G12,'Mercer 26-27'!C11,'Erie School District 26-27'!I11) * $B$8 -> 55833.585 | F47: 53549 | G47: =F47 - E47 -> -2284.5851 | H47: =MAX('Crawford Central School 26-27'!F11, 'Corry 23-24'!G12,'Mercer 26-27'!C11,'Erie School District 26-27'!I11) * $B$8 -> 71018.291 | I47: 53549 | J47: =I47 - H47 -> -17469.291
A48: 11 | B48: =AVERAGE('Crawford Central School 26-27'!F12, 'Corry 23-24'!G13,'Mercer 26-27'!C12,'Erie School District 26-27'!I12) * $B$8 -> 64735.696 | C48: 54299 | D48: =C48 - B48 -> -10436.696 | E48: =MIN('Crawford Central School 26-27'!F12, 'Corry 23-24'!G13,'Mercer 26-27'!C12,'Erie School District 26-27'!I12) * $B$8 -> 57305.81 | F48: 54299 | G48: =F48 - E48 -> -3006.8098 | H48: =MAX('Crawford Central School 26-27'!F12, 'Corry 23-24'!G13,'Mercer 26-27'!C12,'Erie School District 26-27'!I12) * $B$8 -> 72491.448 | I48: 54299 | J48: =I48 - H48 -> -18192.448
A49: 12 | B49: =AVERAGE('Crawford Central School 26-27'!F13, 'Corry 23-24'!G14,'Mercer 26-27'!C13,'Erie School District 26-27'!I13) * $B$8 -> 66309.317 | C49: 54949 | D49: =C49 - B49 -> -11360.317 | E49: =MIN('Crawford Central School 26-27'!F13, 'Corry 23-24'!G14,'Mercer 26-27'!C13,'Erie School District 26-27'!I13) * $B$8 -> 58778.034 | F49: 54949 | G49: =F49 - E49 -> -3829.0345 | H49: =MAX('Crawford Central School 26-27'!F13, 'Corry 23-24'!G14,'Mercer 26-27'!C13,'Erie School District 26-27'!I13) * $B$8 -> 73964.606 | I49: 54949 | J49: =I49 - H49 -> -19015.606
...

Sheet Additional Notes
A1: Need to compare health packages - this IS NOT a Klins task - given recent changes to healh care affordability, I'd expect this to be something they try to use against raising salaries appropriately
A3: Many contracts have steps/columns for additional roles like clubs and sports - Matt wants more clubs and sports, something should get built into the contract about pay for this. Is there an argument for steps? Eg. Year 1 of a club makes x amount, year 2 makes a bit more (more experience), year 3....
A5: Mentoring should get added to the contract - current proposed rate is $300 to mentor a 1st year, $200 to mentor a second
A7: College reimbursement still an issue - note: this has diminishing returns as compared to just a more significant increase in salary. Solving this should be the burden of admin with respect to retention.
A11: Sending Districts | C11: Right to Know email used | D11: Sent | E11: Received | G11: D10 Tech Schools | I11: RTK email used | K11: Sent | L11: Received
A12: Fairview | B12: Fairview: https://www.fairviewschools.org/ | C12: info@fairviewschools.org | D12: 1/12 9am | E12: Failed | G12: Butler County AVTS | I12: openrecords@butlertec.us | K12: 1/12 9am
A13: Fort LeBoeuf | B13: Fort LeBoeuf: https://www.fortleboeuf.net/ | C13: waltersb@flbapps.net | D13: 1/12 9am | G13: Clarion County Career Center | I13: twildeson@clarioncte.org | K13: 1/12 9am | L13: I have resigned my position as the Director of the Career Center. Dr. Ted Pappas is the Interim Director and can be contacted at tpappas@clarioncte.org or by calling 814-226-4391.
A14: General McLane | B14: General McLane: https://www.generalmclane.net/ | C14: jenniferberger@generalmclane.org | D14: 46032 | E14: Replied. Asked for RTK form. Sent back 1/12 | G14: Corry Career & Technical School | I14: openrecords@corrysd.net | K14: 1/12 9am | L14: Respone 1/12 - asked for RTK form filled out. Replied
A15: Girard | B15: Girard: https://www.girardsd.org/ | C15: https://www.girardsd.org/apps/pages/index.jsp?uREC_ID=959141&type=u | D15: 46032 | G15: Crawford County CTC | I15: info@crawfordctc.org | K15: 1/12 9am | L15: Email failed
A16: Harbor Creek | B16: Harbor Creek: https://www.hcsd.iu5.org/ | C16: openrecords@hcsd.iu5.org | D16: 1/12 9am | G16: Erie High School
A17: Iroquois | B17: Iroquois: https://www.iroquoissd.org/ | C17: smurray@iroquois.iu5.org | D17: 1/12 9am | G17: Lawrence County CTC
A18: Millcreek | B18: Millcreek (McDowell) : https://www.mtsd.org/ | C18: info@mtsd.org | D18: 1/12 9am | E18: Email failed | G18: Lenape Technical School
A19: North East | B19: North East : https://www.nesd1.org/ | C19: OpenRecordsRequest@nesd1.org | D19: 1/12 9am | E19: https://www.nesd1.org/contracts https://files.smartsites.parentsquare.com/10215/north_east_education_association.pdf | G19: Mercer County Career Center | J19: akline@mercerccc.org | K19: 1/12 9am
A20: North Western | B20: North Western: https://www.nwsd.org/ | C20: jhannon@nwsd.org | D20: 1/12 9am | G20: Venango Technical Center | J20: webmaster@vtc1.org | K20: 1/12 9am
A21: Union City | B21: Union City: https://www.ucasd.org/ | C21: lrosenthal@ucasd.org | D21: 46032 | G21: Warren County Career Center | J21: woodsb@wcsdpa.org | K21: 1/12 9am
A22: Wattsburg | B22: Wattsburg (Seneca): https://www.wattsburg.org/ | C22: Leslee.Hutchison@wattsburg.org | D22: 1/12 9am | E22: Failed
A26: Right to know email template:
A28: Subject: | B28: Right-to-Know Request – Current Teacher Contract
A29: Content: | B29: Hello, Pursuant to the Pennsylvania Right-to-Know Law, I am requesting a copy of the current collective bargaining agreement for teachers that is presently in effect for the Venango Technical Center. This request includes, but is not limited to, the full contract document and all related salary schedules, appendices, memoranda of understanding, and amendments that are currently in force. I request that the records be provided electronically. If this is not the appropriate address for Right-to-Know Requests, please forward it to the proper contact person. Thank you for your assistance. Sincerely, Jason Klins 8541 Hawick Road Erie Pa 16509
